<?xml version="1.0" ?>
<robot name="thunder" xmlns:xacro="http://www.ros.org/wiki/xacro">

<xacro:include filename="$(find thunder_description)/urdf/materials.xacro" />
<xacro:include filename="$(find thunder_description)/urdf/thunder.trans" />
<xacro:include filename="$(find thunder_description)/urdf/thunder.gazebo" />
<link name="base_link">
  <inertial>
    <origin xyz="-0.001413748491849484 -7.829515970253678e-07 0.06686697168936584" rpy="0 0 0"/>
    <mass value="2.30327736288842"/>
    <inertia ixx="0.006108" iyy="0.010564" izz="0.008297" ixy="0.0" iyz="-0.0" ixz="0.000265"/>
  </inertial>
  <visual>
    <origin xyz="0 0 0" rpy="0 0 0"/>
    <geometry>
      <mesh filename="file://$(find thunder_description)/meshes/base_link.stl" scale="0.001 0.001 0.001"/>
    </geometry>
    <material name="silver"/>
  </visual>
  <collision>
    <origin xyz="0 0 0" rpy="0 0 0"/>
    <geometry>
      <mesh filename="file://$(find thunder_description)/meshes/base_link.stl" scale="0.001 0.001 0.001"/>
    </geometry>
  </collision>
</link>

<link name="left_wheel_front_1">
  <inertial>
    <origin xyz="-1.3877787807814457e-17 0.012500000000000004 0.0" rpy="0 0 0"/>
    <mass value="0.6512177959195153"/>
    <inertia ixx="0.000206" iyy="0.000344" izz="0.000206" ixy="0.0" iyz="-0.0" ixz="0.0"/>
  </inertial>
  <visual>
    <origin xyz="-0.07 -0.043 -0.0325" rpy="0 0 0"/>
    <geometry>
      <mesh filename="file://$(find thunder_description)/meshes/left_wheel_front_1.stl" scale="0.001 0.001 0.001"/>
    </geometry>
    <material name="silver"/>
  </visual>
  <collision>
    <origin xyz="-0.07 -0.043 -0.0325" rpy="0 0 0"/>
    <geometry>
      <mesh filename="file://$(find thunder_description)/meshes/left_wheel_front_1.stl" scale="0.001 0.001 0.001"/>
    </geometry>
  </collision>
</link>

<link name="right_wheel_front_1">
  <inertial>
    <origin xyz="0.0 -0.012500000000000004 0.0" rpy="0 0 0"/>
    <mass value="0.651217795919515"/>
    <inertia ixx="0.000206" iyy="0.000344" izz="0.000206" ixy="-0.0" iyz="0.0" ixz="0.0"/>
  </inertial>
  <visual>
    <origin xyz="-0.07 0.043 -0.0325" rpy="0 0 0"/>
    <geometry>
      <mesh filename="file://$(find thunder_description)/meshes/right_wheel_front_1.stl" scale="0.001 0.001 0.001"/>
    </geometry>
    <material name="silver"/>
  </visual>
  <collision>
    <origin xyz="-0.07 0.043 -0.0325" rpy="0 0 0"/>
    <geometry>
      <mesh filename="file://$(find thunder_description)/meshes/right_wheel_front_1.stl" scale="0.001 0.001 0.001"/>
    </geometry>
  </collision>
</link>

<link name="left_wheel_rear_1">
  <inertial>
    <origin xyz="2.7755575615628914e-17 0.012500000000000004 0.0" rpy="0 0 0"/>
    <mass value="0.6512177959195157"/>
    <inertia ixx="0.000206" iyy="0.000344" izz="0.000206" ixy="0.0" iyz="-0.0" ixz="0.0"/>
  </inertial>
  <visual>
    <origin xyz="0.07 -0.043 -0.0325" rpy="0 0 0"/>
    <geometry>
      <mesh filename="file://$(find thunder_description)/meshes/left_wheel_rear_1.stl" scale="0.001 0.001 0.001"/>
    </geometry>
    <material name="silver"/>
  </visual>
  <collision>
    <origin xyz="0.07 -0.043 -0.0325" rpy="0 0 0"/>
    <geometry>
      <mesh filename="file://$(find thunder_description)/meshes/left_wheel_rear_1.stl" scale="0.001 0.001 0.001"/>
    </geometry>
  </collision>
</link>

<link name="right_wheel_rear_1">
  <inertial>
    <origin xyz="1.3877787807814457e-17 -0.012500000000000004 0.0" rpy="0 0 0"/>
    <mass value="0.6512177959195153"/>
    <inertia ixx="0.000206" iyy="0.000344" izz="0.000206" ixy="-0.0" iyz="0.0" ixz="0.0"/>
  </inertial>
  <visual>
    <origin xyz="0.07 0.043 -0.0325" rpy="0 0 0"/>
    <geometry>
      <mesh filename="file://$(find thunder_description)/meshes/right_wheel_rear_1.stl" scale="0.001 0.001 0.001"/>
    </geometry>
    <material name="silver"/>
  </visual>
  <collision>
    <origin xyz="0.07 0.043 -0.0325" rpy="0 0 0"/>
    <geometry>
      <mesh filename="file://$(find thunder_description)/meshes/right_wheel_rear_1.stl" scale="0.001 0.001 0.001"/>
    </geometry>
  </collision>
</link>

<link name="lidar_1">
  <inertial>
    <origin xyz="3.469446951953614e-18 0.0 0.010000000000000037" rpy="0 0 0"/>
    <mass value="0.6042068071016564"/>
    <inertia ixx="0.000205" iyy="0.000205" izz="0.00037" ixy="0.0" iyz="-0.0" ixz="0.0"/>
  </inertial>
  <visual>
    <origin xyz="0.015 -0.0 -0.1415" rpy="0 0 0"/>
    <geometry>
      <mesh filename="file://$(find thunder_description)/meshes/lidar_1.stl" scale="0.001 0.001 0.001"/>
    </geometry>
    <material name="silver"/>
  </visual>
  <collision>
    <origin xyz="0.015 -0.0 -0.1415" rpy="0 0 0"/>
    <geometry>
      <mesh filename="file://$(find thunder_description)/meshes/lidar_1.stl" scale="0.001 0.001 0.001"/>
    </geometry>
  </collision>
</link>

<link name="camera_1">
  <inertial>
    <origin xyz="0.0 0.0 0.007500000000000007" rpy="0 0 0"/>
    <mass value="0.047099999999999996"/>
    <inertia ixx="7e-06" iyy="1e-06" izz="7e-06" ixy="0.0" iyz="0.0" ixz="0.0"/>
  </inertial>
  <visual>
    <origin xyz="-0.095 -0.0 -0.1075" rpy="0 0 0"/>
    <geometry>
      <mesh filename="file://$(find thunder_description)/meshes/camera_1.stl" scale="0.001 0.001 0.001"/>
    </geometry>
    <material name="silver"/>
  </visual>
  <collision>
    <origin xyz="-0.095 -0.0 -0.1075" rpy="0 0 0"/>
    <geometry>
      <mesh filename="file://$(find thunder_description)/meshes/camera_1.stl" scale="0.001 0.001 0.001"/>
    </geometry>
  </collision>
</link>

<joint name="left_wheel_front_joint" type="continuous">
  <origin xyz="0.07 0.043 0.0325" rpy="0 0 0"/>
  <parent link="base_link"/>
  <child link="left_wheel_front_1"/>
  <axis xyz="0.0 1.0 0.0"/>
</joint>

<joint name="right_wheel_front_joint" type="continuous">
  <origin xyz="0.07 -0.043 0.0325" rpy="0 0 0"/>
  <parent link="base_link"/>
  <child link="right_wheel_front_1"/>
  <axis xyz="0.0 -1.0 0.0"/>
</joint>

<joint name="left_wheel_rear_joint" type="continuous">
  <origin xyz="-0.07 0.043 0.0325" rpy="0 0 0"/>
  <parent link="base_link"/>
  <child link="left_wheel_rear_1"/>
  <axis xyz="0.0 1.0 0.0"/>
</joint>

<joint name="right_wheel_rear_joint" type="continuous">
  <origin xyz="-0.07 -0.043 0.0325" rpy="0 0 0"/>
  <parent link="base_link"/>
  <child link="right_wheel_rear_1"/>
  <axis xyz="0.0 -1.0 0.0"/>
</joint>

<joint name="lidar_joint" type="fixed">
  <origin xyz="-0.015 0.0 0.1415" rpy="0 0 0"/>
  <parent link="base_link"/>
  <child link="lidar_1"/>
</joint>

<joint name="camera_joint" type="fixed">
  <origin xyz="0.095 0.0 0.1075" rpy="0 0 0"/>
  <parent link="base_link"/>
  <child link="camera_1"/>
</joint>

</robot>
