<?xml version="1.0" ?>
<robot name="thunder" xmlns:xacro="http://www.ros.org/wiki/xacro">

<xacro:include filename="$(find thunder_description)/urdf/materials.xacro" />
<xacro:include filename="$(find thunder_description)/urdf/thunder.trans" />
<xacro:include filename="$(find thunder_description)/urdf/thunder.gazebo" />
<link name="base_link">
  <inertial>
    <origin xyz="-0.0015343514816687786 -7.81885672034026e-07 0.06692160954933128" rpy="0 0 0"/>
    <mass value="2.306417362888421"/>
    <inertia ixx="0.006113" iyy="0.010594" izz="0.008322" ixy="0.0" iyz="-0.0" ixz="0.000276"/>
  </inertial>
  <visual>
    <origin xyz="0 0 0" rpy="0 0 0"/>
    <geometry>
      <mesh filename="file://$(find thunder_description)/meshes/base_link.stl" scale="0.001 0.001 0.001"/>
    </geometry>
    <material name="silver"/>
  </visual>
  <collision>
    <origin xyz="0 0 0" rpy="0 0 0"/>
    <geometry>
      <mesh filename="file://$(find thunder_description)/meshes/base_link.stl" scale="0.001 0.001 0.001"/>
    </geometry>
  </collision>
</link>

<link name="front_wheel_left">
  <inertial>
    <origin xyz="-1.3877787807814457e-17 0.012500000000000004 0.0" rpy="0 0 0"/>
    <mass value="0.6512177959195153"/>
    <inertia ixx="0.000206" iyy="0.000344" izz="0.000206" ixy="0.0" iyz="-0.0" ixz="0.0"/>
  </inertial>
  <visual>
    <origin xyz="-0.07 -0.043 -0.0325" rpy="0 0 0"/>
    <geometry>
      <mesh filename="file://$(find thunder_description)/meshes/front_wheel_left.stl" scale="0.001 0.001 0.001"/>
    </geometry>
    <material name="silver"/>
  </visual>
  <collision>
    <origin xyz="-0.07 -0.043 -0.0325" rpy="0 0 0"/>
    <geometry>
      <mesh filename="file://$(find thunder_description)/meshes/front_wheel_left.stl" scale="0.001 0.001 0.001"/>
    </geometry>
  </collision>
</link>

<link name="front_wheel_right">
  <inertial>
    <origin xyz="0.0 -0.012500000000000004 0.0" rpy="0 0 0"/>
    <mass value="0.651217795919515"/>
    <inertia ixx="0.000206" iyy="0.000344" izz="0.000206" ixy="-0.0" iyz="0.0" ixz="0.0"/>
  </inertial>
  <visual>
    <origin xyz="-0.07 0.043 -0.0325" rpy="0 0 0"/>
    <geometry>
      <mesh filename="file://$(find thunder_description)/meshes/front_wheel_right.stl" scale="0.001 0.001 0.001"/>
    </geometry>
    <material name="silver"/>
  </visual>
  <collision>
    <origin xyz="-0.07 0.043 -0.0325" rpy="0 0 0"/>
    <geometry>
      <mesh filename="file://$(find thunder_description)/meshes/front_wheel_right.stl" scale="0.001 0.001 0.001"/>
    </geometry>
  </collision>
</link>

<link name="rear_wheel_left">
  <inertial>
    <origin xyz="2.7755575615628914e-17 0.012500000000000004 0.0" rpy="0 0 0"/>
    <mass value="0.6512177959195157"/>
    <inertia ixx="0.000206" iyy="0.000344" izz="0.000206" ixy="0.0" iyz="-0.0" ixz="0.0"/>
  </inertial>
  <visual>
    <origin xyz="0.07 -0.043 -0.0325" rpy="0 0 0"/>
    <geometry>
      <mesh filename="file://$(find thunder_description)/meshes/rear_wheel_left.stl" scale="0.001 0.001 0.001"/>
    </geometry>
    <material name="silver"/>
  </visual>
  <collision>
    <origin xyz="0.07 -0.043 -0.0325" rpy="0 0 0"/>
    <geometry>
      <mesh filename="file://$(find thunder_description)/meshes/rear_wheel_left.stl" scale="0.001 0.001 0.001"/>
    </geometry>
  </collision>
</link>

<link name="rear_wheel_right">
  <inertial>
    <origin xyz="1.3877787807814457e-17 -0.012500000000000004 0.0" rpy="0 0 0"/>
    <mass value="0.6512177959195153"/>
    <inertia ixx="0.000206" iyy="0.000344" izz="0.000206" ixy="-0.0" iyz="0.0" ixz="0.0"/>
  </inertial>
  <visual>
    <origin xyz="0.07 0.043 -0.0325" rpy="0 0 0"/>
    <geometry>
      <mesh filename="file://$(find thunder_description)/meshes/rear_wheel_right.stl" scale="0.001 0.001 0.001"/>
    </geometry>
    <material name="silver"/>
  </visual>
  <collision>
    <origin xyz="0.07 0.043 -0.0325" rpy="0 0 0"/>
    <geometry>
      <mesh filename="file://$(find thunder_description)/meshes/rear_wheel_right.stl" scale="0.001 0.001 0.001"/>
    </geometry>
  </collision>
</link>

<link name="lidar">
  <inertial>
    <origin xyz="3.469446951953614e-18 0.0 0.010000000000000037" rpy="0 0 0"/>
    <mass value="0.6042068071016564"/>
    <inertia ixx="0.000205" iyy="0.000205" izz="0.00037" ixy="0.0" iyz="-0.0" ixz="0.0"/>
  </inertial>
  <visual>
    <origin xyz="0.015 -0.0 -0.1415" rpy="0 0 0"/>
    <geometry>
      <mesh filename="file://$(find thunder_description)/meshes/lidar.stl" scale="0.001 0.001 0.001"/>
    </geometry>
    <material name="silver"/>
  </visual>
  <collision>
    <origin xyz="0.015 -0.0 -0.1415" rpy="0 0 0"/>
    <geometry>
      <mesh filename="file://$(find thunder_description)/meshes/lidar.stl" scale="0.001 0.001 0.001"/>
    </geometry>
  </collision>
</link>

<link name="camera">
  <inertial>
    <origin xyz="0.0 0.0 0.007500000000000007" rpy="0 0 0"/>
    <mass value="0.047099999999999996"/>
    <inertia ixx="7e-06" iyy="1e-06" izz="7e-06" ixy="0.0" iyz="0.0" ixz="0.0"/>
  </inertial>
  <visual>
    <origin xyz="-0.095 -0.0 -0.1075" rpy="0 0 0"/>
    <geometry>
      <mesh filename="file://$(find thunder_description)/meshes/camera.stl" scale="0.001 0.001 0.001"/>
    </geometry>
    <material name="silver"/>
  </visual>
  <collision>
    <origin xyz="-0.095 -0.0 -0.1075" rpy="0 0 0"/>
    <geometry>
      <mesh filename="file://$(find thunder_description)/meshes/camera.stl" scale="0.001 0.001 0.001"/>
    </geometry>
  </collision>
</link>

<link name="imu">
  <inertial>
    <origin xyz="0.0 0.0 0.0010000000000000009" rpy="0 0 0"/>
    <mass value="0.0062799999999999774"/>
    <inertia ixx="0.0" iyy="0.0" izz="0.0" ixy="0.0" iyz="0.0" ixz="-0.0"/>
  </inertial>
  <visual>
    <origin xyz="0.09 -0.0 -0.1075" rpy="0 0 0"/>
    <geometry>
      <mesh filename="file://$(find thunder_description)/meshes/imu.stl" scale="0.001 0.001 0.001"/>
    </geometry>
    <material name="silver"/>
  </visual>
  <collision>
    <origin xyz="0.09 -0.0 -0.1075" rpy="0 0 0"/>
    <geometry>
      <mesh filename="file://$(find thunder_description)/meshes/imu.stl" scale="0.001 0.001 0.001"/>
    </geometry>
  </collision>
</link>

<joint name="front_wheel_left_joint" type="continuous">
  <origin xyz="0.07 0.043 0.0325" rpy="0 0 0"/>
  <parent link="base_link"/>
  <child link="front_wheel_left"/>
  <axis xyz="0.0 1.0 0.0"/>
</joint>

<joint name="front_wheel_right_joint" type="continuous">
  <origin xyz="0.07 -0.043 0.0325" rpy="0 0 0"/>
  <parent link="base_link"/>
  <child link="front_wheel_right"/>
  <axis xyz="0.0 -1.0 0.0"/>
</joint>

<joint name="rear_wheel_left_joint" type="continuous">
  <origin xyz="-0.07 0.043 0.0325" rpy="0 0 0"/>
  <parent link="base_link"/>
  <child link="rear_wheel_left"/>
  <axis xyz="0.0 1.0 0.0"/>
</joint>

<joint name="rear_wheel_right_joint" type="continuous">
  <origin xyz="-0.07 -0.043 0.0325" rpy="0 0 0"/>
  <parent link="base_link"/>
  <child link="rear_wheel_right"/>
  <axis xyz="0.0 -1.0 0.0"/>
</joint>

<joint name="lidar_joint" type="fixed">
  <origin xyz="-0.015 0.0 0.1415" rpy="0 0 0"/>
  <parent link="base_link"/>
  <child link="lidar"/>
</joint>

<joint name="camera_link" type="fixed">
  <origin xyz="0.095 0.0 0.1075" rpy="0 0 0"/>
  <parent link="base_link"/>
  <child link="camera"/>
</joint>

<joint name="imu_link" type="fixed">
  <origin xyz="-0.09 0.0 0.1075" rpy="0 0 0"/>
  <parent link="base_link"/>
  <child link="imu"/>
</joint>

</robot>
